<?xml version="1.0"?>
<robot xmlns:xacro="http://www.ros.org/wiki/xacro">
	<material name="white">
	    <color rgba="1 1 1 1"/>
	</material>

	<material name="orange">
	    <color rgba="1 0.3 0.1 1"/>
	</material>

	<material name="blue">
		<color rgba="0.2 0.2 1 1"/>
	</material>

	<material name="black">
	    <color rgba="0 0 0 1"/>
	</material>
	
	<link name="base_link">
	</link>
	
	<joint name="chassis_joint" type="fixed">
		<parent link="base_link"/>
		<child link="chassis"/>
		<origin xyz="0 0 0"/>
	</joint>
	
	<link name="chassis">
		<visual>
		    <origin xyz="0 0 0.03915" rpy="0 0 0"/>
		    <geometry>
		        <box size="0.25 0.25 0.12"/>
		    </geometry>
		    <material name="white"/>
		</visual>
	</link>
	<joint name="left_wheel_joint" type="continuous">
		<parent link="base_link"/>
		<child link="left_wheel"/>
		<origin xyz="0 0.1375 0" rpy="-${pi/2} 0 0"/>
		<axis xyz="0 0 1"/>
	</joint>

	<link name="left_wheel">
		<visual>
			<geometry>
				<cylinder length="0.01" radius="0.045" />/>
			</geometry>
			<material name="blue"/>
		</visual>
	</link>

	<joint name="right_wheel_joint" type="continuous">
		<parent link="base_link"/>
		<child link="right_wheel"/>
		<origin xyz="0 -0.1375 0" rpy="${pi/2} 0 0"/>
		<axis xyz="0 0 -1"/>
	</joint>

	<link name="right_wheel">
		<visual>
			<geometry>
				<cylinder length="0.01" radius="0.045" />/>
			</geometry>
			<material name="blue"/>
		</visual>
	</link>
</robot>
